Workbook

Sheet PECD1
A1: id | B1: level | C1: per_km2 | D1: area_km2 | E1: country
A2: AL | B2: PECD1 | C2: 118.76031 | D2: 28676.889 | E2: AL
A3: AT | B3: PECD1 | C3: 109.70394 | D3: 83924.463 | E3: AT
A4: BA | B4: PECD1 | C4: 62.665619 | D4: 51543.415 | E4: BA
A5: BE | B5: PECD1 | C5: 381.70247 | D5: 30661.697 | E5: BE
A6: BG | B6: PECD1 | C6: 62.779601 | D6: 110964.02 | E6: BG
A7: CH | B7: PECD1 | C7: 222.63859 | D7: 41287.334 | E7: CH
A8: CY | B8: PECD1 | C8: 97.780244 | D8: 9249.1067 | E8: CY
A9: CZ | B9: PECD1 | C9: 135.9732 | D9: 78869.26 | E9: CZ
A10: DE | B10: PECD1 | C10: 237.30252 | D10: 357105.08 | E10: DE
A11: DK | B11: PECD1 | C11: 141.67889 | D11: 42585.057 | E11: DK
A12: EE | B12: PECD1 | C12: 30.491143 | D12: 45335.415 | E12: EE
A13: ES | B13: PECD1 | C13: 90.844476 | D13: 498515.19 | E13: ES
... A40: XK | B40: PECD1 | C40: 174.45203 | D40: 10776.601 | E40: XK

Sheet PECD2
A1: id | B1: level | C1: per_km2 | D1: area_km2 | E1: country
A2: AL00 | B2: PECD2 | C2: 118.76031 | D2: 28676.889 | E2: AL
A3: AT01 | B3: PECD2 | C3: 77.241467 | D3: 28553.527 | E3: AT
A4: AT02 | B4: PECD2 | C4: 92.871886 | D4: 31777.701 | E4: AT
A5: AT03 | B5: PECD2 | C5: 171.66246 | D5: 23593.235 | E5: AT
A6: BA00 | B6: PECD2 | C6: 62.665619 | D6: 51543.415 | E6: BA
A7: BE01 | B7: PECD2 | C7: 398.17568 | D7: 5593.2457 | E7: BE
A8: BE02 | B8: PECD2 | C8: 582.34376 | D8: 11556.277 | E8: BE
A9: BE03 | B9: PECD2 | C9: 203.28522 | D9: 13512.174 | E9: BE
A10: BG01 | B10: PECD2 | C10: 50.347068 | D10: 68304.827 | E10: BG
A11: BG02 | B11: PECD2 | C11: 82.686263 | D11: 42659.19 | E11: BG
A12: CH00 | B12: PECD2 | C12: 222.63859 | D12: 41287.334 | E12: CH
A13: CY00 | B13: PECD2 | C13: 97.780244 | D13: 9249.1067 | E13: CY
... A127: XK00 | B127: PECD2 | C127: 174.45203 | D127: 10776.601 | E127: XK

Sheet NUTS2
A1: id | B1: level | C1: per_km2 | D1: area_km2 | E1: country
A2: AL01 | B2: NUTS2 | C2: 119.72908 | D2: 10824.949 | E2: AL
A3: AL02 | B3: NUTS2 | C3: 238.92326 | D3: 4966.3234 | E3: AL
A4: AL03 | B4: NUTS2 | C4: 70.957614 | D4: 13008.397 | E4: AL
A5: AT11 | B5: NUTS2 | C5: 79.210482 | D5: 3965.7586 | E5: AT
A6: AT12 | B6: NUTS2 | C6: 89.838249 | D6: 19196.99 | E6: AT
A7: AT13 | B7: NUTS2 | C7: 4864.3 | D7: 413.48586 | E7: AT
A8: AT21 | B8: NUTS2 | C8: 60.549783 | D8: 9543.8557 | E8: AT
A9: AT22 | B9: NUTS2 | C9: 77.02114 | D9: 16413.638 | E9: AT
A10: AT31 | B10: NUTS2 | C10: 128.28196 | D10: 11984.846 | E10: AT
A11: AT32 | B11: NUTS2 | C11: 80.375972 | D11: 7157.4782 | E11: AT
A12: AT33 | B12: NUTS2 | C12: 60.858663 | D12: 12648.211 | E12: AT
A13: AT34 | B13: NUTS2 | C13: 164.92594 | D13: 2620.654 | E13: AT
... A324: XK00 | B324: NUTS2 | C324: 174.45203 | D324: 10776.601 | E324: XK

Sheet IC1
A1: id | B1: level | C1: per_km2 | D1: area_km2 | E1: country
A2: BEC1 | B2: IC1 | C2: 931.4342 | D2: 1483.5238 | E2: BE
A3: BEC2 | B3: IC1 | C3: 904.30347 | D3: 3613.0482 | E3: BE
A4: BEC3 | B4: IC1 | C4: 246.45623 | D4: 6393.6465 | E4: BE
A5: BEC4 | B5: IC1 | C5: 514.00347 | D5: 1285.3851 | E5: BE
A6: BEC5 | B6: IC1 | C6: 361.50537 | D6: 3786.8437 | E6: BE
A7: BEC6 | B7: IC1 | C7: 170.38906 | D7: 8317.0295 | E7: BE
A8: BEC7 | B8: IC1 | C8: 314.71855 | D8: 2194.7515 | E8: BE
A9: BEC8 | B9: IC1 | C9: 373.40104 | D9: 3592.0577 | E9: BE
A10: NLC1 | B10: IC1 | C10: 219.71232 | D10: 4388.8767 | E10: NL
A11: NLC2 | B11: IC1 | C11: 256.1243 | D11: 6512.2776 | E11: NL
A12: NLC3 | B12: IC1 | C12: 372.47778 | D12: 10969.216 | E12: NL
A13: NLC4 | B13: IC1 | C13: 1206.5959 | D13: 3610.4841 | E13: NL
... A18: NLC9 | B18: IC1 | C18: 912.7 | D18: 660.40053 | E18: NL

Sheet NUTS3
A1: id | B1: level | C1: per_km2 | D1: area_km2 | E1: country
A2: AL011 | B2: NUTS3 | C2: 68.2 | D2: 2470.3072 | E2: AL | F2: =C2*D2 -> 168474.95
A3: AL012 | B3: NUTS3 | C3: 88 | D3: 772.5367 | E3: AL | F3: =C3*D3 -> 67983.23
A4: AL013 | B4: NUTS3 | C4: 30 | D4: 2391.4485 | E4: AL | F4: =C4*D4 -> 71743.456
A5: AL014 | B5: NUTS3 | C5: 50.9 | D5: 1662.3526 | E5: AL | F5: =C5*D5 -> 84613.75
A6: AL015 | B6: NUTS3 | C6: 256 | D6: 3528.3043 | E6: AL | F6: =C6*D6 -> 903245.89
A7: AL021 | B7: NUTS3 | C7: 79.8 | D7: 3314.1018 | E7: AL | F7: =C7*D7 -> 264465.33
A8: AL022 | B8: NUTS3 | C8: 558.1 | D8: 1652.2215 | E8: AL | F8: =C8*D8 -> 922104.82
A9: AL031 | B9: NUTS3 | C9: 64.8 | D9: 1801.9661 | E9: AL | F9: =C9*D9 -> 116767.4
A10: AL032 | B10: NUTS3 | C10: 98.6 | D10: 1881.6305 | E10: AL | F10: =C10*D10 -> 185528.76
A11: AL033 | B11: NUTS3 | C11: 21.5 | D11: 2880.6602 | E11: AL | F11: =C11*D11 -> 61934.195
A12: AL034 | B12: NUTS3 | C12: 111.8 | D12: 3736.5955 | E12: AL | F12: =C12*D12 -> 417751.38
A13: AL035 | B13: NUTS3 | C13: 52.1 | D13: 2707.5447 | E13: AL | F13: =C13*D13 -> 141063.08
... A1489: XK00 | B1489: NUTS3 | C1489: 174.45203 | D1489: 10776.601 | E1489: XK | F1489: =C1489*D1489 -> 1880000

Sheet OFF1
A1: id | B1: level | C1: area_km2 | D1: country
A2: AS | B2: OFF1 | C2: 1230203
A3: AT | B3: OFF1 | C3: 817781.46
A4: BL | B4: OFF1 | C4: 462330.71
A5: BS | B5: OFF1 | C5: 364779.35
A6: EM | B6: OFF1 | C6: 704298.13
A7: MA | B7: OFF1 | C7: 602831.78
A8: NS | B8: OFF1 | C8: 504310.55
A9: WM | B9: OFF1 | C9: 902135.84

Sheet OFF2
A1: id | B1: level | C1: area_km2 | D1: country
A2: ASNO | B2: OFF2 | C2: 823989.82 | D2: NO
A3: ASUK | B3: OFF2 | C3: 406203.67 | D3: UK
A4: ATFR | B4: OFF2 | C4: 244796.26 | D4: FR
A5: ATIE | B5: OFF2 | C5: 426851.41 | D5: IE
A6: ATUK | B6: OFF2 | C6: 146142.36 | D6: UK
A7: BLBG | B7: OFF2 | C7: 34732.455 | D7: BG
A8: BLRO | B8: OFF2 | C8: 29590.484 | D8: RO
A9: BLTR | B9: OFF2 | C9: 261993.49 | D9: TR
A10: BLUA | B10: OFF2 | C10: 136023.23 | D10: UA
A11: BSDE | B11: OFF2 | C11: 12007.26 | D11: DE
A12: BSDK | B12: OFF2 | C12: 12075.951 | D12: DK
A13: BSEE | B13: OFF2 | C13: 36413.409 | D13: EE
... A39: WMMT | B39: OFF2 | C39: 52902.813 | D39: MT

Sheet OFF2_map
A1: source | B1: PECD1 | C1: PECD2 | D1: NUTS2 | E1: NUTS3
A2: ASNO | B2: NO | C2: NOM1 | D2: NO06 | E2: NO060
A3: ASUK | B3: UK | C3: UK05 | D3: UKM5 | E3: UKM50
A4: ATFR | B4: FR | C4: FR01 | D4: FRD1 | E4: FRD11
A5: ATIE | B5: IE | C5: IE00 | D5: IE04 | E5: IE041
A6: ATUK | B6: UK | C6: UK02 | D6: UKD1 | E6: UKD11
A7: BLBG | B7: BG | C7: BG01 | D7: BG33 | E7: BG331
A8: BLRO | B8: RO | C8: RO03 | D8: RO22 | E8: RO223
A9: BLTR | B9: TR | C9: TR01 | D9: TR10 | E9: TR100
A10: BLUA | B10: UA | C10: UA02 | D10: UA02 | E10: UA02
A11: BSDE | B11: DE | C11: DE01 | D11: DE80 | E11: DE803
A12: BSDK | B12: DK | C12: DKE1 | D12: DK02 | E12: DK022
... A39: WMMT | B39: MT | C39: MT00 | D39: MT00 | E39: MT001

Sheet OFF3
A1: id | B1: level | C1: area_km2 | D1: country
A2: EMAL00 | B2: OFF3 | C2: 12141.491 | D2: AL
A3: EMBA00 | B3: OFF3 | C3: 8.8571525 | D3: BA
A4: NSBE01 | B4: OFF3 | C4: 3490.0601 | D4: BE
A5: BLBG01 | B5: OFF3 | C5: 34732.455 | D5: BG
A6: EMCY00 | B6: OFF3 | C6: 98416.7 | D6: CY
A7: NSDE011 | B7: OFF3 | C7: 21849.476 | D7: DE
A8: NSDE012 | B8: OFF3 | C8: 13675.741 | D8: DE
A9: NSDE013 | B9: OFF3 | C9: 6764.1152 | D9: DE
A10: BSDE02 | B10: OFF3 | C10: 12007.26 | D10: DE
A11: BSDKBI | B11: OFF3 | C11: 12075.951 | D11: DK
A12: NSDKE1 | B12: OFF3 | C12: 13640.67 | D12: DK
A13: NSDKKF | B13: OFF3 | C13: 637.37665 | D13: DK
... A87: ATIE05 | B87: OFF3 | C87: 4322.2904 | D87: IE

Sheet OFF3_map
A1: source | B1: PECD1 | C1: PECD2 | D1: NUTS2 | E1: NUTS3 | F1: IC1
A2: EMAL00 | B2: AL | C2: AL00 | D2: AL01 | E2: AL012
A3: EMBA00 | B3: BA | C3: BA00 | D3: BA00 | E3: BA00
A4: NSBE01 | B4: BE | C4: BE01 | D4: BE25 | E4: BE251 | F4: BEC8
A5: BLBG01 | B5: BG | C5: BG01 | D5: BG33 | E5: BG331
A6: EMCY00 | B6: CY | C6: CY00 | D6: CY00 | E6: CY000
A7: NSDE011 | B7: DE | C7: DE01 | D7: DE50 | E7: DE501
A8: NSDE012 | B8: DE | C8: DE01 | D8: DEF0 | E8: DEF09
A9: NSDE013 | B9: DE | C9: DE01 | D9: DE94 | E9: DE94C
A10: BSDE02 | B10: DE | C10: DE01 | D10: DE80 | E10: DE803
A11: BSDKBI | B11: DK | C11: DKE1 | D11: DK02 | E11: DK022
A12: NSDKE1 | B12: DK | C12: DKE1 | D12: DK01 | E12: DK011
A13: NSDKKF | B13: DK | C13: DKE1 | D13: DK02 | E13: DK022
A14: NSDKW11 | B14: DK | C14: DKE1 | D14: DK02 | E14: DK022
A15: NSDKW12 | B15: DK | C15: DKW1 | D15: DK03 | E15: DK032
A16: BSEE00 | B16: EE | C16: EE00 | D16: EE00 | E16: EE001
... A47: WMMT00 | B47: MT | C47: MT00 | D47: MT00 | E47: MT001
A48: NSNL011 | B48: NL | C48: NL01 | D48: NL11 | E48: NL112 | F48: NLC1
A49: NSNL012 | B49: NL | C49: NL01 | D49: NL12 | E49: NL124 | F49: NLC2
A50: NSNL031 | B50: NL | C50: NL03 | D50: NL12 | E50: NL125 | F50: NLC2
A51: NSNL032 | B51: NL | C51: NL03 | D51: NL32 | E51: NL321 | F51: NLC2
A52: NSNL033 | B52: NL | C52: NL03 | D52: NL34 | E52: NL341 | F52: NLC7
A53: ASNOM1 | B53: NO | C53: NOM1 | D53: NO06 | E53: NO060
A54: ASNON1 | B54: NO | C54: NOM1 | D54: NO06 | E54: NO060
A55: NSNOS21 | B55: NO | C55: NOS1 | D55: NO08 | E55: NO081
A56: NSNOS22 | B56: NO | C56: NOS2 | D56: NO09 | E56: NO092
A57: ASNOS3 | B57: NO | C57: NOS2 | D57: NO0A | E57: NO0A1
A58: BSPL04 | B58: PL | C58: PL04 | D58: PL42 | E58: PL424
A59: BSPL05 | B59: PL | C59: PL04 | D59: PL42 | E59: PL426
A60: MAPT01 | B60: PT | C60: PT01 | D60: PT11 | E60: PT111
A61: MAPT02 | B61: PT | C61: PT01 | D61: PT15 | E61: PT150
A62: BLRO03 | B62: RO | C62: RO03 | D62: RO22 | E62: RO223
A63: BSSE01 | B63: SE | C63: SE01 | D63: SE33 | E63: SE332
A64: BSSE02 | B64: SE | C64: SE02 | D64: SE12 | E64: SE121
... A87: ATIE05 | B87: IE | C87: IE00 | D87: IE06 | E87: IE061

Sheet PECD1_NUTS2
A1: source | B1: target | C1: area | D1: population
A2: AL | B2: AL01 | C2: 0.3766 | D2: 0.3811
A3: AL | B3: AL02 | C3: 0.1742 | D3: 0.3498
A4: AL | B4: AL03 | C4: 0.4492 | D4: 0.2691
A5: AT | B5: AT11 | C5: 0.0472 | D5: 0.0341
A6: AT | B6: AT12 | C6: 0.2289 | D6: 0.1873
A7: AT | B7: AT13 | C7: 0.0049 | D7: 0.2185
A8: AT | B8: AT21 | C8: 0.1137 | D8: 0.0628
A9: AT | B9: AT22 | C9: 0.1957 | D9: 0.1373
A10: AT | B10: AT31 | C10: 0.1428 | D10: 0.167
A11: AT | B11: AT32 | C11: 0.0853 | D11: 0.0625
A12: AT | B12: AT33 | C12: 0.1505 | D12: 0.0836
A13: AT | B13: AT34 | C13: 0.0309 | D13: 0.0469
... A324: XK | B324: XK00 | C324: 1 | D324: 1

Sheet NUTS2_PECD1
A1: source | B1: target | C1: area | D1: population
A2: AL01 | B2: AL | C2: 1 | D2: 1
A3: AL02 | B3: AL | C3: 1 | D3: 1
A4: AL03 | B4: AL | C4: 1 | D4: 1
A5: AT11 | B5: AT | C5: 1 | D5: 1
A6: AT12 | B6: AT | C6: 1 | D6: 1
A7: AT13 | B7: AT | C7: 1 | D7: 1
A8: AT21 | B8: AT | C8: 1 | D8: 1
A9: AT22 | B9: AT | C9: 1 | D9: 1
A10: AT31 | B10: AT | C10: 1 | D10: 1
A11: AT32 | B11: AT | C11: 1 | D11: 1
A12: AT33 | B12: AT | C12: 1 | D12: 1
A13: AT34 | B13: AT | C13: 1 | D13: 1
... A324: XK00 | B324: XK | C324: 1 | D324: 1

Sheet PECD1_NUTS3
A1: source | B1: target | C1: area | D1: population
A2: AL | B2: AL011 | C2: 0.0853 | D2: 0.0497
A3: AL | B3: AL012 | C3: 0.0259 | D3: 0.0191
A4: AL | B4: AL013 | C4: 0.0839 | D4: 0.0212
A5: AL | B5: AL014 | C5: 0.058 | D5: 0.0249
A6: AL | B6: AL015 | C6: 0.1236 | D6: 0.2662
A7: AL | B7: AL021 | C7: 0.1167 | D7: 0.078
A8: AL | B8: AL022 | C8: 0.0575 | D8: 0.2719
A9: AL | B9: AL031 | C9: 0.0635 | D9: 0.0344
A10: AL | B10: AL032 | C10: 0.0626 | D10: 0.0516
A11: AL | B11: AL033 | C11: 0.1003 | D11: 0.0183
A12: AL | B12: AL034 | C12: 0.1313 | D12: 0.1232
A13: AL | B13: AL035 | C13: 0.0915 | D13: 0.0416
... A1489: XK | B1489: XK00 | C1489: 1 | D1489: 1

Sheet NUTS3_PECD1
A1: source | B1: target | C1: area | D1: population
A2: AL011 | B2: AL | C2: 1 | D2: 1
A3: AL012 | B3: AL | C3: 1 | D3: 1
A4: AL013 | B4: AL | C4: 1 | D4: 1
A5: AL014 | B5: AL | C5: 1 | D5: 1
A6: AL015 | B6: AL | C6: 1 | D6: 1
A7: AL021 | B7: AL | C7: 1 | D7: 1
A8: AL022 | B8: AL | C8: 1 | D8: 1
A9: AL031 | B9: AL | C9: 1 | D9: 1
A10: AL032 | B10: AL | C10: 1 | D10: 1
A11: AL033 | B11: AL | C11: 1 | D11: 1
A12: AL034 | B12: AL | C12: 1 | D12: 1
A13: AL035 | B13: AL | C13: 1 | D13: 1
... A1489: XK00 | B1489: XK | C1489: 1 | D1489: 1

Sheet PECD1_IC1
A1: source | B1: target | C1: area | D1: population
A2: AL | B2: AL | C2: 1 | D2: 1
A3: AT | B3: AT | C3: 1 | D3: 1
A4: BA | B4: BA | C4: 1 | D4: 1
A5: BE | B5: BEC1 | C5: =VLOOKUP(B5,'IC1'!$A$1:$E$18,4,FALSE)/SUMIF('IC1'!$E:$E,PECD1_IC1!A5,'IC1'!$D:$D) -> 0.048376378 | D5: =(VLOOKUP(B5,'IC1'!$A$1:$E$18,3,FALSE)*VLOOKUP(B5,'IC1'!$A$1:$E$18,4,FALSE))/SUMPRODUCT('IC1'!$D$2:$D$9,'IC1'!$C$2:$C$9) -> 0.11806619
A6: BE | B6: BEC2 | C6: =VLOOKUP(B6,'IC1'!$A$1:$E$18,4,FALSE)/SUMIF('IC1'!$E:$E,PECD1_IC1!A6,'IC1'!$D:$D) -> 0.11781825 | D6: =(VLOOKUP(B6,'IC1'!$A$1:$E$18,3,FALSE)*VLOOKUP(B6,'IC1'!$A$1:$E$18,4,FALSE))/SUMPRODUCT('IC1'!$D$2:$D$9,'IC1'!$C$2:$C$9) -> 0.27916874
A7: BE | B7: BEC3 | C7: =VLOOKUP(B7,'IC1'!$A$1:$E$18,4,FALSE)/SUMIF('IC1'!$E:$E,PECD1_IC1!A7,'IC1'!$D:$D) -> 0.20849106 | D7: =(VLOOKUP(B7,'IC1'!$A$1:$E$18,3,FALSE)*VLOOKUP(B7,'IC1'!$A$1:$E$18,4,FALSE))/SUMPRODUCT('IC1'!$D$2:$D$9,'IC1'!$C$2:$C$9) -> 0.13463788
A8: BE | B8: BEC4 | C8: =VLOOKUP(B8,'IC1'!$A$1:$E$18,4,FALSE)/SUMIF('IC1'!$E:$E,PECD1_IC1!A8,'IC1'!$D:$D) -> 0.04191525 | D8: =(VLOOKUP(B8,'IC1'!$A$1:$E$18,3,FALSE)*VLOOKUP(B8,'IC1'!$A$1:$E$18,4,FALSE))/SUMPRODUCT('IC1'!$D$2:$D$9,'IC1'!$C$2:$C$9) -> 0.056451845
A9: BE | B9: BEC5 | C9: =VLOOKUP(B9,'IC1'!$A$1:$E$18,4,FALSE)/SUMIF('IC1'!$E:$E,PECD1_IC1!A9,'IC1'!$D:$D) -> 0.12348557 | D9: =(VLOOKUP(B9,'IC1'!$A$1:$E$18,3,FALSE)*VLOOKUP(B9,'IC1'!$A$1:$E$18,4,FALSE))/SUMPRODUCT('IC1'!$D$2:$D$9,'IC1'!$C$2:$C$9) -> 0.11696905
A10: BE | B10: BEC6 | C10: =VLOOKUP(B10,'IC1'!$A$1:$E$18,4,FALSE)/SUMIF('IC1'!$E:$E,PECD1_IC1!A10,'IC1'!$D:$D) -> 0.27121085 | D10: =(VLOOKUP(B10,'IC1'!$A$1:$E$18,3,FALSE)*VLOOKUP(B10,'IC1'!$A$1:$E$18,4,FALSE))/SUMPRODUCT('IC1'!$D$2:$D$9,'IC1'!$C$2:$C$9) -> 0.12108457
A11: BE | B11: BEC7 | C11: =VLOOKUP(B11,'IC1'!$A$1:$E$18,4,FALSE)/SUMIF('IC1'!$E:$E,PECD1_IC1!A11,'IC1'!$D:$D) -> 0.071568872 | D11: =(VLOOKUP(B11,'IC1'!$A$1:$E$18,3,FALSE)*VLOOKUP(B11,'IC1'!$A$1:$E$18,4,FALSE))/SUMPRODUCT('IC1'!$D$2:$D$9,'IC1'!$C$2:$C$9) -> 0.059018277
A12: BE | B12: BEC8 | C12: =VLOOKUP(B12,'IC1'!$A$1:$E$18,4,FALSE)/SUMIF('IC1'!$E:$E,PECD1_IC1!A12,'IC1'!$D:$D) -> 0.11713377 | D12: =(VLOOKUP(B12,'IC1'!$A$1:$E$18,3,FALSE)*VLOOKUP(B12,'IC1'!$A$1:$E$18,4,FALSE))/SUMPRODUCT('IC1'!$D$2:$D$9,'IC1'!$C$2:$C$9) -> 0.11460344
A13: BG | B13: BG | C13: 1 | D13: 1
A14: CH | B14: =A14 -> CH | C14: 1 | D14: 1
A15: CY | B15: =A15 -> CY | C15: 1 | D15: 1
A16: CZ | B16: =A16 -> CZ | C16: 1 | D16: 1
A17: DE | B17: =A17 -> DE | C17: 1 | D17: 1
A18: DK | B18: =A18 -> DK | C18: 1 | D18: 1
A19: EE | B19: =A19 -> EE | C19: 1 | D19: 1
A20: ES | B20: =A20 -> ES | C20: 1 | D20: 1
A21: FI | B21: =A21 -> FI | C21: 1 | D21: 1
A22: FR | B22: =A22 -> FR | C22: 1 | D22: 1
A23: GR | B23: =A23 -> GR | C23: 1 | D23: 1
A24: HR | B24: =A24 -> HR | C24: 1 | D24: 1
A25: HU | B25: =A25 -> HU | C25: 1 | D25: 1
... A34: MT | B34: =A34 -> MT | C34: 1 | D34: 1
A35: NL | B35: NLC1 | C35: =VLOOKUP(B35,'IC1'!$A$1:$E$18,4,FALSE)/SUMIF('IC1'!$E:$E,PECD1_IC1!A35,'IC1'!$D:$D) -> 0.11741094 | D35: =(VLOOKUP(B35,'IC1'!$A$1:$E$18,3,FALSE)*VLOOKUP(B35,'IC1'!$A$1:$E$18,4,FALSE))/SUMPRODUCT('IC1'!$D$10:$D$18,'IC1'!$C$10:$C$18) -> 0.050310457
A36: NL | B36: NLC2 | C36: =VLOOKUP(B36,'IC1'!$A$1:$E$18,4,FALSE)/SUMIF('IC1'!$E:$E,PECD1_IC1!A36,'IC1'!$D:$D) -> 0.17421601 | D36: =(VLOOKUP(B36,'IC1'!$A$1:$E$18,3,FALSE)*VLOOKUP(B36,'IC1'!$A$1:$E$18,4,FALSE))/SUMPRODUCT('IC1'!$D$10:$D$18,'IC1'!$C$10:$C$18) -> 0.08702302
A37: NL | B37: NLC3 | C37: =VLOOKUP(B37,'IC1'!$A$1:$E$18,4,FALSE)/SUMIF('IC1'!$E:$E,PECD1_IC1!A37,'IC1'!$D:$D) -> 0.29344772 | D37: =(VLOOKUP(B37,'IC1'!$A$1:$E$18,3,FALSE)*VLOOKUP(B37,'IC1'!$A$1:$E$18,4,FALSE))/SUMPRODUCT('IC1'!$D$10:$D$18,'IC1'!$C$10:$C$18) -> 0.21317016
A38: NL | B38: NLC4 | C38: =VLOOKUP(B38,'IC1'!$A$1:$E$18,4,FALSE)/SUMIF('IC1'!$E:$E,PECD1_IC1!A38,'IC1'!$D:$D) -> 0.09658743 | D38: =(VLOOKUP(B38,'IC1'!$A$1:$E$18,3,FALSE)*VLOOKUP(B38,'IC1'!$A$1:$E$18,4,FALSE))/SUMPRODUCT('IC1'!$D$10:$D$18,'IC1'!$C$10:$C$18) -> 0.22728865
A39: NL | B39: NLC5 | C39: =VLOOKUP(B39,'IC1'!$A$1:$E$18,4,FALSE)/SUMIF('IC1'!$E:$E,PECD1_IC1!A39,'IC1'!$D:$D) -> 0.031484179 | D39: =(VLOOKUP(B39,'IC1'!$A$1:$E$18,3,FALSE)*VLOOKUP(B39,'IC1'!$A$1:$E$18,4,FALSE))/SUMPRODUCT('IC1'!$D$10:$D$18,'IC1'!$C$10:$C$18) -> 0.10837376
A40: NL | B40: NLC6 | C40: =VLOOKUP(B40,'IC1'!$A$1:$E$18,4,FALSE)/SUMIF('IC1'!$E:$E,PECD1_IC1!A40,'IC1'!$D:$D) -> 0.074952674 | D40: =(VLOOKUP(B40,'IC1'!$A$1:$E$18,3,FALSE)*VLOOKUP(B40,'IC1'!$A$1:$E$18,4,FALSE))/SUMPRODUCT('IC1'!$D$10:$D$18,'IC1'!$C$10:$C$18) -> 0.12953977
A41: NL | B41: NLC7 | C41: =VLOOKUP(B41,'IC1'!$A$1:$E$18,4,FALSE)/SUMIF('IC1'!$E:$E,PECD1_IC1!A41,'IC1'!$D:$D) -> 0.051698608 | D41: =(VLOOKUP(B41,'IC1'!$A$1:$E$18,3,FALSE)*VLOOKUP(B41,'IC1'!$A$1:$E$18,4,FALSE))/SUMPRODUCT('IC1'!$D$10:$D$18,'IC1'!$C$10:$C$18) -> 0.021883142
A42: NL | B42: NLC8 | C42: =VLOOKUP(B42,'IC1'!$A$1:$E$18,4,FALSE)/SUMIF('IC1'!$E:$E,PECD1_IC1!A42,'IC1'!$D:$D) -> 0.14253545 | D42: =(VLOOKUP(B42,'IC1'!$A$1:$E$18,3,FALSE)*VLOOKUP(B42,'IC1'!$A$1:$E$18,4,FALSE))/SUMPRODUCT('IC1'!$D$10:$D$18,'IC1'!$C$10:$C$18) -> 0.13096355
A43: NL | B43: NLC9 | C43: =VLOOKUP(B43,'IC1'!$A$1:$E$18,4,FALSE)/SUMIF('IC1'!$E:$E,PECD1_IC1!A43,'IC1'!$D:$D) -> 0.017666991 | D43: =(VLOOKUP(B43,'IC1'!$A$1:$E$18,3,FALSE)*VLOOKUP(B43,'IC1'!$A$1:$E$18,4,FALSE))/SUMPRODUCT('IC1'!$D$10:$D$18,'IC1'!$C$10:$C$18) -> 0.031447486
A44: NO | B44: =A44 -> NO | C44: 1 | D44: 1
A45: PL | B45: =A45 -> PL | C45: 1 | D45: 1
A46: PT | B46: =A46 -> PT | C46: 1 | D46: 1
A47: RO | B47: =A47 -> RO | C47: 1 | D47: 1
A48: RS | B48: =A48 -> RS | C48: 1 | D48: 1
...

Sheet IC1_PECD1
A1: source | B1: target | C1: area | D1: population
A2: AL | B2: AL | C2: 1 | D2: 1
A3: AT | B3: AT | C3: 1 | D3: 1
A4: BA | B4: BA | C4: 1 | D4: 1
A5: BEC1 | B5: BE | C5: 1 | D5: 1
A6: BEC2 | B6: BE | C6: 1 | D6: 1
A7: BEC3 | B7: BE | C7: 1 | D7: 1
A8: BEC4 | B8: BE | C8: 1 | D8: 1
A9: BEC5 | B9: BE | C9: 1 | D9: 1
A10: BEC6 | B10: BE | C10: 1 | D10: 1
A11: BEC7 | B11: BE | C11: 1 | D11: 1
A12: BEC8 | B12: BE | C12: 1 | D12: 1
A13: BG | B13: BG | C13: 1 | D13: 1
... A55: XK | B55: XK | C55: 1 | D55: 1

Sheet PECD2_NUTS2
A1: source | B1: target | C1: area | D1: population
A2: AL00 | B2: AL01 | C2: 0.3766 | D2: 0.3811
A3: AL00 | B3: AL02 | C3: 0.1742 | D3: 0.3498
A4: AL00 | B4: AL03 | C4: 0.4492 | D4: 0.2691
A5: AT01 | B5: AT21 | C5: 0.2159 | D5: 0.1942
A6: AT01 | B6: AT32 | C6: 0.2506 | D6: 0.2608
A7: AT01 | B7: AT33 | C7: 0.4426 | D7: 0.349
A8: AT01 | B8: AT34 | C8: 0.0909 | D8: 0.196
A9: AT02 | B9: AT21 | C9: 0.1063 | D9: 0.0507
A10: AT02 | B10: AT22 | C10: 0.5167 | D10: 0.4284
A11: AT02 | B11: AT31 | C11: 0.377 | D11: 0.5209
A12: AT03 | B12: AT11 | C12: 0.1679 | D12: 0.0776
A13: AT03 | B13: AT12 | C13: 0.8145 | D13: 0.4258
... A380: XK00 | B380: XK00 | C380: 1 | D380: 1

Sheet NUTS2_PECD2
A1: source | B1: target | C1: area | D1: population
A2: AL01 | B2: AL00 | C2: 1 | D2: 1
A3: AL02 | B3: AL00 | C3: 1 | D3: 1
A4: AL03 | B4: AL00 | C4: 1 | D4: 1
A5: AT21 | B5: AT01 | C5: 0.646 | D5: 0.7411
A6: AT32 | B6: AT01 | C6: 1 | D6: 1
A7: AT33 | B7: AT01 | C7: 1 | D7: 1
A8: AT34 | B8: AT01 | C8: 1 | D8: 1
A9: AT21 | B9: AT02 | C9: 0.354 | D9: 0.2589
A10: AT22 | B10: AT02 | C10: 1 | D10: 1
A11: AT31 | B11: AT02 | C11: 1 | D11: 1
A12: AT11 | B12: AT03 | C12: 1 | D12: 1
A13: AT12 | B13: AT03 | C13: 1 | D13: 1
... A380: XK00 | B380: XK00 | C380: 1 | D380: 1

Sheet PECD2_NUTS3
A1: source | B1: target | C1: area | D1: population
A2: AL00 | B2: AL011 | C2: 0.0853 | D2: 0.0497
A3: AL00 | B3: AL012 | C3: 0.0259 | D3: 0.0191
A4: AL00 | B4: AL013 | C4: 0.0839 | D4: 0.0212
A5: AL00 | B5: AL014 | C5: 0.058 | D5: 0.0249
A6: AL00 | B6: AL015 | C6: 0.1236 | D6: 0.2662
A7: AL00 | B7: AL021 | C7: 0.1167 | D7: 0.078
A8: AL00 | B8: AL022 | C8: 0.0575 | D8: 0.2719
A9: AL00 | B9: AL031 | C9: 0.0635 | D9: 0.0344
A10: AL00 | B10: AL032 | C10: 0.0626 | D10: 0.0516
A11: AL00 | B11: AL033 | C11: 0.1003 | D11: 0.0183
A12: AL00 | B12: AL034 | C12: 0.1313 | D12: 0.1232
A13: AL00 | B13: AL035 | C13: 0.0915 | D13: 0.0416
... A1496: XK00 | B1496: XK00 | C1496: 1 | D1496: 1

Sheet NUTS3_PECD2
A1: source | B1: target | C1: area | D1: population
A2: AL011 | B2: AL00 | C2: 1 | D2: 1
A3: AL012 | B3: AL00 | C3: 1 | D3: 1
A4: AL013 | B4: AL00 | C4: 1 | D4: 1
A5: AL014 | B5: AL00 | C5: 1 | D5: 1
A6: AL015 | B6: AL00 | C6: 1 | D6: 1
A7: AL021 | B7: AL00 | C7: 1 | D7: 1
A8: AL022 | B8: AL00 | C8: 1 | D8: 1
A9: AL031 | B9: AL00 | C9: 1 | D9: 1
A10: AL032 | B10: AL00 | C10: 1 | D10: 1
A11: AL033 | B11: AL00 | C11: 1 | D11: 1
A12: AL034 | B12: AL00 | C12: 1 | D12: 1
A13: AL035 | B13: AL00 | C13: 1 | D13: 1
... A1496: XK00 | B1496: XK00 | C1496: 1 | D1496: 1

Sheet PECD1_PECD2
A1: source | B1: target | C1: area | D1: population
A2: AL | B2: AL00 | C2: 1 | D2: 1
A3: AT | B3: AT01 | C3: 0.3402 | D3: 0.2396
A4: AT | B4: AT02 | C4: 0.3786 | D4: 0.3206
A5: AT | B5: AT03 | C5: 0.2811 | D5: 0.4399
A6: BA | B6: BA00 | C6: 1 | D6: 1
A7: BE | B7: BE01 | C7: 0.1824 | D7: 0.1903
A8: BE | B8: BE02 | C8: 0.3769 | D8: 0.575
A9: BE | B9: BE03 | C9: 0.4407 | D9: 0.2347
A10: BG | B10: BG01 | C10: 0.6156 | D10: 0.4937
A11: BG | B11: BG02 | C11: 0.3844 | D11: 0.5063
A12: CH | B12: CH00 | C12: 1 | D12: 1
A13: CY | B13: CY00 | C13: 1 | D13: 1
... A127: XK | B127: XK00 | C127: 1 | D127: 1

Sheet PECD2_PECD1
A1: source | B1: target | C1: area | D1: population | E1: capacity | F1: potential
A2: AL00 | B2: AL | C2: 1 | D2: 1 | E2: 0 | F2: 1
A3: AT01 | B3: AT | C3: 1 | D3: 1 | E3: 0.002 | F3: 0.249
A4: AT02 | B4: AT | C4: 1 | D4: 1 | E4: 0.091 | F4: 0.417
A5: AT03 | B5: AT | C5: 1 | D5: 1 | E5: 0.908 | F5: 0.334
A6: BA00 | B6: BA | C6: 1 | D6: 1 | E6: 1 | F6: 1
A7: BE01 | B7: BE | C7: 1 | D7: 1 | E7: 0.229 | F7: 0.167
A8: BE02 | B8: BE | C8: 1 | D8: 1 | E8: 0.439 | F8: 0.307
A9: BE03 | B9: BE | C9: 1 | D9: 1 | E9: 0.332 | F9: 0.526
A10: BG01 | B10: BG | C10: 1 | D10: 1 | E10: 1 | F10: 0.63
A11: BG02 | B11: BG | C11: 1 | D11: 1 | E11: 0 | F11: 0.37
A12: CH00 | B12: CH | C12: 1 | D12: 1 | E12: 1 | F12: 1
A13: CY00 | B13: CY | C13: 1 | D13: 1 | E13: 1 | F13: 1
... A127: XK00 | B127: XK | C127: 1 | D127: 1 | E127: 1 | F127: 1

Sheet NUTS2_NUTS3
A1: source | B1: target | C1: area | D1: population
A2: AL01 | B2: AL011 | C2: 0.2282 | D2: 0.13
A3: AL01 | B3: AL012 | C3: 0.0714 | D3: 0.0525
A4: AL01 | B4: AL013 | C4: 0.2209 | D4: 0.0554
A5: AL01 | B5: AL014 | C5: 0.1536 | D5: 0.0653
A6: AL01 | B6: AL015 | C6: 0.3259 | D6: 0.6968
A7: AL02 | B7: AL021 | C7: 0.6673 | D7: 0.2229
A8: AL02 | B8: AL022 | C8: 0.3327 | D8: 0.7771
A9: AL03 | B9: AL031 | C9: 0.1385 | D9: 0.1265
A10: AL03 | B10: AL032 | C10: 0.1446 | D10: 0.201
A11: AL03 | B11: AL033 | C11: 0.2214 | D11: 0.0671
A12: AL03 | B12: AL034 | C12: 0.2872 | D12: 0.4526
A13: AL03 | B13: AL035 | C13: 0.2081 | D13: 0.1528
... A1489: XK00 | B1489: XK00 | C1489: 1 | D1489: 1

Sheet NUTS3_NUTS2
A1: source | B1: target | C1: area | D1: population
A2: AL011 | B2: AL01 | C2: 1 | D2: 1
A3: AL012 | B3: AL01 | C3: 1 | D3: 1
A4: AL013 | B4: AL01 | C4: 1 | D4: 1
A5: AL014 | B5: AL01 | C5: 1 | D5: 1
A6: AL015 | B6: AL01 | C6: 1 | D6: 1
A7: AL021 | B7: AL02 | C7: 1 | D7: 1
A8: AL022 | B8: AL02 | C8: 1 | D8: 1
A9: AL031 | B9: AL03 | C9: 1 | D9: 1
A10: AL032 | B10: AL03 | C10: 1 | D10: 1
A11: AL033 | B11: AL03 | C11: 1 | D11: 1
A12: AL034 | B12: AL03 | C12: 1 | D12: 1
A13: AL035 | B13: AL03 | C13: 1 | D13: 1
... A1489: XK00 | B1489: XK00 | C1489: 1 | D1489: 1

Sheet IC1_NUTS3
A1: source | B1: target | C1: area | D1: population
A2: BEC2 | B2: BE100 | C2: =VLOOKUP($B2,NUTS3!$A$1:$D$1489,4,FALSE)/VLOOKUP($A2,'IC1'!$A$1:$D$18,4,FALSE) -> 0.044958624 | D2: =(VLOOKUP($B2,NUTS3!$A$1:$D$1489,4,FALSE)*VLOOKUP($B2,NUTS3!$A$1:$D$1489,3,FALSE))/(VLOOKUP($A2,'IC1'!$A$1:$D$18,4,FALSE)*VLOOKUP($A2,'IC1'!$A$1:$D$18,3,FALSE)) -> 0.37670539
A3: BEC1 | B3: BE211 | C3: =VLOOKUP(B3,NUTS3!$A$1:$D$1489,4,FALSE)/VLOOKUP(A3,'IC1'!$A$1:$D$18,4,FALSE) -> 0.67614692 | D3: =(VLOOKUP($B3,NUTS3!$A$1:$D$1489,4,FALSE)*VLOOKUP($B3,NUTS3!$A$1:$D$1489,3,FALSE))/(VLOOKUP($A3,'IC1'!$A$1:$D$18,4,FALSE)*VLOOKUP($A3,'IC1'!$A$1:$D$18,3,FALSE)) -> 0.80511812
A4: BEC2 | B4: BE212 | C4: =VLOOKUP(B4,NUTS3!$A$1:$D$1489,4,FALSE)/VLOOKUP(A4,'IC1'!$A$1:$D$18,4,FALSE) -> 0.14168324 | D4: =(VLOOKUP($B4,NUTS3!$A$1:$D$1489,4,FALSE)*VLOOKUP($B4,NUTS3!$A$1:$D$1489,3,FALSE))/(VLOOKUP($A4,'IC1'!$A$1:$D$18,4,FALSE)*VLOOKUP($A4,'IC1'!$A$1:$D$18,3,FALSE)) -> 0.10998701
A5: BEC5 | B5: BE213 | C5: =VLOOKUP(B5,NUTS3!$A$1:$D$1489,4,FALSE)/VLOOKUP(A5,'IC1'!$A$1:$D$18,4,FALSE) -> 0.35913704 | D5: =(VLOOKUP($B5,NUTS3!$A$1:$D$1489,4,FALSE)*VLOOKUP($B5,NUTS3!$A$1:$D$1489,3,FALSE))/(VLOOKUP($A5,'IC1'!$A$1:$D$18,4,FALSE)*VLOOKUP($A5,'IC1'!$A$1:$D$18,3,FALSE)) -> 0.34711097
A6: BEC5 | B6: BE223 | C6: =VLOOKUP(B6,NUTS3!$A$1:$D$1489,4,FALSE)/VLOOKUP(A6,'IC1'!$A$1:$D$18,4,FALSE) -> 0.16721206 | D6: =(VLOOKUP($B6,NUTS3!$A$1:$D$1489,4,FALSE)*VLOOKUP($B6,NUTS3!$A$1:$D$1489,3,FALSE))/(VLOOKUP($A6,'IC1'!$A$1:$D$18,4,FALSE)*VLOOKUP($A6,'IC1'!$A$1:$D$18,3,FALSE)) -> 0.15222316
A7: BEC5 | B7: BE224 | C7: =VLOOKUP(B7,NUTS3!$A$1:$D$1489,4,FALSE)/VLOOKUP(A7,'IC1'!$A$1:$D$18,4,FALSE) -> 0.2332712 | D7: =(VLOOKUP($B7,NUTS3!$A$1:$D$1489,4,FALSE)*VLOOKUP($B7,NUTS3!$A$1:$D$1489,3,FALSE))/(VLOOKUP($A7,'IC1'!$A$1:$D$18,4,FALSE)*VLOOKUP($A7,'IC1'!$A$1:$D$18,3,FALSE)) -> 0.31141082
A8: BEC5 | B8: BE225 | C8: =VLOOKUP(B8,NUTS3!$A$1:$D$1489,4,FALSE)/VLOOKUP(A8,'IC1'!$A$1:$D$18,4,FALSE) -> 0.2403797 | D8: =(VLOOKUP($B8,NUTS3!$A$1:$D$1489,4,FALSE)*VLOOKUP($B8,NUTS3!$A$1:$D$1489,3,FALSE))/(VLOOKUP($A8,'IC1'!$A$1:$D$18,4,FALSE)*VLOOKUP($A8,'IC1'!$A$1:$D$18,3,FALSE)) -> 0.18925505
A9: BEC2 | B9: BE231 | C9: =VLOOKUP(B9,NUTS3!$A$1:$D$1489,4,FALSE)/VLOOKUP(A9,'IC1'!$A$1:$D$18,4,FALSE) -> 0.13103075 | D9: =(VLOOKUP($B9,NUTS3!$A$1:$D$1489,4,FALSE)*VLOOKUP($B9,NUTS3!$A$1:$D$1489,3,FALSE))/(VLOOKUP($A9,'IC1'!$A$1:$D$18,4,FALSE)*VLOOKUP($A9,'IC1'!$A$1:$D$18,3,FALSE)) -> 0.091140136
A10: BEC2 | B10: BE232 | C10: =VLOOKUP(B10,NUTS3!$A$1:$D$1489,4,FALSE)/VLOOKUP(A10,'IC1'!$A$1:$D$18,4,FALSE) -> 0.095972408 | D10: =(VLOOKUP($B10,NUTS3!$A$1:$D$1489,4,FALSE)*VLOOKUP($B10,NUTS3!$A$1:$D$1489,3,FALSE))/(VLOOKUP($A10,'IC1'!$A$1:$D$18,4,FALSE)*VLOOKUP($A10,'IC1'!$A$1:$D$18,3,FALSE)) -> 0.063783254
A11: BEC4 | B11: BE233 | C11: =VLOOKUP(B11,NUTS3!$A$1:$D$1489,4,FALSE)/VLOOKUP(A11,'IC1'!$A$1:$D$18,4,FALSE) -> 0.26130374 | D11: =(VLOOKUP($B11,NUTS3!$A$1:$D$1489,4,FALSE)*VLOOKUP($B11,NUTS3!$A$1:$D$1489,3,FALSE))/(VLOOKUP($A11,'IC1'!$A$1:$D$18,4,FALSE)*VLOOKUP($A11,'IC1'!$A$1:$D$18,3,FALSE)) -> 0.13268447
A12: BEC4 | B12: BE234 | C12: =VLOOKUP(B12,NUTS3!$A$1:$D$1489,4,FALSE)/VLOOKUP(A12,'IC1'!$A$1:$D$18,4,FALSE) -> 0.73869626 | D12: =(VLOOKUP($B12,NUTS3!$A$1:$D$1489,4,FALSE)*VLOOKUP($B12,NUTS3!$A$1:$D$1489,3,FALSE))/(VLOOKUP($A12,'IC1'!$A$1:$D$18,4,FALSE)*VLOOKUP($A12,'IC1'!$A$1:$D$18,3,FALSE)) -> 0.86731553
A13: BEC8 | B13: BE235 | C13: =VLOOKUP(B13,NUTS3!$A$1:$D$1489,4,FALSE)/VLOOKUP(A13,'IC1'!$A$1:$D$18,4,FALSE) -> 0.11764145 | D13: =(VLOOKUP($B13,NUTS3!$A$1:$D$1489,4,FALSE)*VLOOKUP($B13,NUTS3!$A$1:$D$1489,3,FALSE))/(VLOOKUP($A13,'IC1'!$A$1:$D$18,4,FALSE)*VLOOKUP($A13,'IC1'!$A$1:$D$18,3,FALSE)) -> 0.093507991
A14: BEC1 | B14: BE236 | C14: =VLOOKUP(B14,NUTS3!$A$1:$D$1489,4,FALSE)/VLOOKUP(A14,'IC1'!$A$1:$D$18,4,FALSE) -> 0.32385308 | D14: =(VLOOKUP($B14,NUTS3!$A$1:$D$1489,4,FALSE)*VLOOKUP($B14,NUTS3!$A$1:$D$1489,3,FALSE))/(VLOOKUP($A14,'IC1'!$A$1:$D$18,4,FALSE)*VLOOKUP($A14,'IC1'!$A$1:$D$18,3,FALSE)) -> 0.19488188
... A85: NLC9 | B85: NL423 | C85: =VLOOKUP(B85,NUTS3!$A$1:$D$1489,4,FALSE)/VLOOKUP(A85,'IC1'!$A$1:$D$18,4,FALSE) -> 1 | D85: =(VLOOKUP($B85,NUTS3!$A$1:$D$1489,4,FALSE)*VLOOKUP($B85,NUTS3!$A$1:$D$1489,3,FALSE))/(VLOOKUP($A85,'IC1'!$A$1:$D$18,4,FALSE)*VLOOKUP($A85,'IC1'!$A$1:$D$18,3,FALSE)) -> 1

Sheet NUTS3_IC1
A1: source | B1: target | C1: area | D1: population
A2: BE100 | B2: BEC2 | C2: 1 | D2: 1
A3: BE211 | B3: BEC1 | C3: 1 | D3: 1
A4: BE212 | B4: BEC2 | C4: 1 | D4: 1
A5: BE213 | B5: BEC5 | C5: 1 | D5: 1
A6: BE223 | B6: BEC5 | C6: 1 | D6: 1
A7: BE224 | B7: BEC5 | C7: 1 | D7: 1
A8: BE225 | B8: BEC5 | C8: 1 | D8: 1
A9: BE231 | B9: BEC2 | C9: 1 | D9: 1
A10: BE232 | B10: BEC2 | C10: 1 | D10: 1
A11: BE233 | B11: BEC4 | C11: 1 | D11: 1
A12: BE234 | B12: BEC4 | C12: 1 | D12: 1
A13: BE235 | B13: BEC8 | C13: 1 | D13: 1
... A85: NL423 | B85: NLC9 | C85: 1 | D85: 1

Sheet OFF1_OFF2
A1: source | B1: target | C1: area
A2: AS | B2: ASNO | C2: 0.6698
A3: AS | B3: ASUK | C3: 0.3302
A4: AT | B4: ATFR | C4: 0.2993
A5: AT | B5: ATIE | C5: 0.522
A6: AT | B6: ATUK | C6: 0.1787
A7: BL | B7: BLBG | C7: 0.0751
A8: BL | B8: BLRO | C8: 0.064
A9: BL | B9: BLTR | C9: 0.5666
A10: BL | B10: BLUA | C10: 0.2942
A11: BS | B11: BSDE | C11: 0.0329
A12: BS | B12: BSDK | C12: 0.0331
A13: BS | B13: BSEE | C13: 0.0998
... A39: WM | B39: WMMT | C39: 0.0586

Sheet OFF2_OFF1
A1: source | B1: target | C1: area
A2: ASNO | B2: AS | C2: 1
A3: ASUK | B3: AS | C3: 1
A4: ATFR | B4: AT | C4: 1
A5: ATIE | B5: AT | C5: 1
A6: ATUK | B6: AT | C6: 1
A7: BLBG | B7: BL | C7: 1
A8: BLRO | B8: BL | C8: 1
A9: BLTR | B9: BL | C9: 1
A10: BLUA | B10: BL | C10: 1
A11: BSDE | B11: BS | C11: 1
A12: BSDK | B12: BS | C12: 1
A13: BSEE | B13: BS | C13: 1
... A39: WMMT | B39: WM | C39: 1

Sheet OFF1_OFF3
A1: source | B1: target | C1: area
A2: AS | B2: ASNOM1 | C2: 0.0998
A3: AS | B3: ASNON1 | C3: 0.5268
A4: AS | B4: ASNOS3 | C4: 0.0432
A5: AS | B5: ASUK051 | C5: 0.1439
A6: AS | B6: ASUK053 | C6: 0.1863
A7: AT | B7: ATFR01 | C7: 0.0387
A8: AT | B8: ATFR04 | C8: 0.1159
A9: AT | B9: ATFR08 | C9: 0.1304
A10: AT | B10: ATFR09 | C10: 0.0143
A11: AT | B11: ATUK02 | C11: 0.1149
A12: AT | B12: ATUK031 | C12: 0.0378
A13: AT | B13: ATUK043 | C13: 0.0194
... A87: WM | B87: WMMT00 | C87: 0.0586

Sheet OFF3_OFF1
A1: source | B1: target | C1: area
A2: ASNOM1 | B2: AS | C2: 1
A3: ASNON1 | B3: AS | C3: 1
A4: ASNOS3 | B4: AS | C4: 1
A5: ASUK051 | B5: AS | C5: 1
A6: ASUK053 | B6: AS | C6: 1
A7: ATFR01 | B7: AT | C7: 1
A8: ATFR04 | B8: AT | C8: 1
A9: ATFR08 | B9: AT | C9: 1
A10: ATFR09 | B10: AT | C10: 1
A11: ATUK02 | B11: AT | C11: 1
A12: ATUK031 | B12: AT | C12: 1
A13: ATUK043 | B13: AT | C13: 1
... A87: WMMT00 | B87: WM | C87: 1

Sheet OFF2_OFF3
A1: source | B1: target | C1: area
A2: ASNO | B2: ASNOM1 | C2: 0.149
A3: ASNO | B3: ASNON1 | C3: 0.7865
A4: ASNO | B4: ASNOS3 | C4: 0.0645
A5: ASUK | B5: ASUK051 | C5: 0.4357
A6: ASUK | B6: ASUK053 | C6: 0.5643
A7: ATFR | B7: ATFR01 | C7: 0.1293
A8: ATFR | B8: ATFR04 | C8: 0.3871
A9: ATFR | B9: ATFR08 | C9: 0.4358
A10: ATFR | B10: ATFR09 | C10: 0.0478
A11: ATIE | B11: ATIE00 | C11: 0.268
A12: ATIE | B12: ATIE01 | C12: 0.2859
A13: ATIE | B13: ATIE02 | C13: 0.2164
... A87: WMMT | B87: WMMT00 | C87: 1

Sheet OFF3_OFF2
A1: source | B1: target | C1: area | D1: capacity | E1: potential
A2: ASNOM1 | B2: ASNO | C2: 1 | D2: 0 | E2: 0.194
A3: ASNON1 | B3: ASNO | C3: 1 | D3: 0 | E3: 0.66
A4: ASNOS3 | B4: ASNO | C4: 1 | D4: 0 | E4: 0.146
A5: ASUK051 | B5: ASUK | C5: 1 | D5: 1 | E5: 0.45
A6: ASUK053 | B6: ASUK | C6: 1 | D6: 0 | E6: 0.55
A7: ATFR01 | B7: ATFR | C7: 1 | D7: 0 | E7: 0.097
A8: ATFR04 | B8: ATFR | C8: 1 | D8: 0 | E8: 0.178
A9: ATFR08 | B9: ATFR | C9: 1 | D9: 1 | E9: 0.394
A10: ATFR09 | B10: ATFR | C10: 1 | D10: 0 | E10: 0.331
A11: ATIE00 | B11: ATIE | C11: 1 | D11: 0 | E11: 0.134
A12: ATIE01 | B12: ATIE | C12: 1 | D12: 0 | E12: 0.276
A13: ATIE02 | B13: ATIE | C13: 1 | D13: 0 | E13: 0.149
... A38: EMAL00 | B38: EMAL | C38: 1 | D38: 0 | E38: 1
A39: EMBA00 | B39: EMBA | C39: 1 | D39: 0
A40: EMCY00 | B40: EMCY | C40: 1 | D40: 0
A41: EMGR01 | B41: EMGR | C41: 1 | D41: 0 | E41: 0.177
A42: EMGR02 | B42: EMGR | C42: 1 | D42: 0 | E42: 0.702
A43: EMGR03 | B43: EMGR | C43: 1 | D43: 0 | E43: 0.121
A44: EMHR01 | B44: EMHR | C44: 1 | D44: 0 | E44: 1
A45: EMITS1 | B45: EMIT | C45: 1 | D45: 0 | E45: 1
A46: EMME00 | B46: EMME | C46: 1 | D46: 0
A47: EMSI00 | B47: EMSI | C47: 1 | D47: 0
A48: MAES01 | B48: MAES | C48: 1 | D48: 0 | E48: 0.674
A49: MAES02 | B49: MAES | C49: 1 | D49: 0 | E49: 0.326
A50: MAES04 | B50: MAES | C50: 1 | D50: 0
A51: MAPT01 | B51: MAPT | C51: 1 | D51: 0 | E51: 0.255
A52: MAPT02 | B52: MAPT | C52: 1 | D52: 0 | E52: 0.745
A53: NSBE01 | B53: NSBE | C53: 1 | D53: 1 | E53: 1
A54: NSDE011 | B54: NSDE | C54: 1 | D54: 0.6 | E54: 0.594
A55: NSDE012 | B55: NSDE | C55: 1 | D55: 0.4 | E55: 0.406
A56: NSDE013 | B56: NSDE | C56: 1 | D56: 0
A57: NSDKE1 | B57: NSDK | C57: 1 | D57: 0.249 | E57: 0.232
A58: NSDKKF | B58: NSDK | C58: 1 | D58: 0 | E58: 0.011
A59: NSDKW11 | B59: NSDK | C59: 1 | D59: 0.751 | E59: 0.669
A60: NSDKW12 | B60: NSDK | C60: 1 | D60: 0 | E60: 0.089
A61: NSFR13 | B61: NSFR | C61: 1 | D61: 0 | E61: 1
A62: NSNL011 | B62: NSNL | C62: 1 | D62: 0.627 | E62: 0.229
A63: NSNL012 | B63: NSNL | C63: 1 | D63: 0 | E63: 0.143
A64: NSNL031 | B64: NSNL | C64: 1 | D64: 0.373 | E64: 0.407
...
